2025-03-11 17:31:29,239 INFO    MainThread:3284794 [wandb_setup.py:_flush():67] Current SDK version is 0.19.8
2025-03-11 17:31:29,239 INFO    MainThread:3284794 [wandb_setup.py:_flush():67] Configure stats pid to 3284794
2025-03-11 17:31:29,239 INFO    MainThread:3284794 [wandb_setup.py:_flush():67] Loading settings from /home/deena/.config/wandb/settings
2025-03-11 17:31:29,239 INFO    MainThread:3284794 [wandb_setup.py:_flush():67] Loading settings from /home/deena/nmep/sp25-nmep-hw2/wandb/settings
2025-03-11 17:31:29,239 INFO    MainThread:3284794 [wandb_setup.py:_flush():67] Loading settings from environment variables
2025-03-11 17:31:29,239 INFO    MainThread:3284794 [wandb_init.py:setup_run_log_directory():647] Logging user logs to /home/deena/nmep/sp25-nmep-hw2/wandb/run-20250311_173129-alexnet-throughput/logs/debug.log
2025-03-11 17:31:29,239 INFO    MainThread:3284794 [wandb_init.py:setup_run_log_directory():648] Logging internal logs to /home/deena/nmep/sp25-nmep-hw2/wandb/run-20250311_173129-alexnet-throughput/logs/debug-internal.log
2025-03-11 17:31:29,240 INFO    MainThread:3284794 [wandb_init.py:init():761] calling init triggers
2025-03-11 17:31:29,240 INFO    MainThread:3284794 [wandb_init.py:init():766] wandb.init called with sweep_config: {}
config: {'dataset': 'cifar10', 'batch_size': 512, 'image_size': 70, 'learning_rate': 0.0003, 'epochs': 5, 'optimizer': 'adamw', '_wandb': {}}
2025-03-11 17:31:29,240 INFO    MainThread:3284794 [wandb_init.py:init():784] starting backend
2025-03-11 17:31:29,240 INFO    MainThread:3284794 [wandb_init.py:init():788] sending inform_init request
2025-03-11 17:31:29,242 INFO    MainThread:3284794 [backend.py:_multiprocessing_setup():101] multiprocessing start_methods=fork,spawn,forkserver, using: spawn
2025-03-11 17:31:29,242 INFO    MainThread:3284794 [wandb_init.py:init():798] backend started and connected
2025-03-11 17:31:29,246 INFO    MainThread:3284794 [wandb_init.py:init():891] updated telemetry
2025-03-11 17:31:29,252 INFO    MainThread:3284794 [wandb_init.py:init():915] communicating run to backend with 90.0 second timeout
2025-03-11 17:32:59,257 ERROR   MainThread:3284794 [wandb_init.py:init():1478] error in wandb.init()
Traceback (most recent call last):
  File "/home/deena/miniconda3/envs/vision-zoo/lib/python3.10/asyncio/locks.py", line 214, in wait
    await fut
asyncio.exceptions.CancelledError

During handling of the above exception, another exception occurred:

Traceback (most recent call last):
  File "/home/deena/miniconda3/envs/vision-zoo/lib/python3.10/asyncio/tasks.py", line 456, in wait_for
    return fut.result()
asyncio.exceptions.CancelledError

The above exception was the direct cause of the following exception:

Traceback (most recent call last):
  File "/home/deena/miniconda3/envs/vision-zoo/lib/python3.10/site-packages/wandb/sdk/mailbox/response_handle.py", line 109, in wait_async
    await asyncio.wait_for(evt.wait(), timeout=timeout)
  File "/home/deena/miniconda3/envs/vision-zoo/lib/python3.10/asyncio/tasks.py", line 458, in wait_for
    raise exceptions.TimeoutError() from exc
asyncio.exceptions.TimeoutError

The above exception was the direct cause of the following exception:

Traceback (most recent call last):
  File "/home/deena/miniconda3/envs/vision-zoo/lib/python3.10/site-packages/wandb/sdk/wandb_init.py", line 941, in init
    result = wait_with_progress(
  File "/home/deena/miniconda3/envs/vision-zoo/lib/python3.10/site-packages/wandb/sdk/mailbox/wait_with_progress.py", line 24, in wait_with_progress
    return wait_all_with_progress(
  File "/home/deena/miniconda3/envs/vision-zoo/lib/python3.10/site-packages/wandb/sdk/mailbox/wait_with_progress.py", line 87, in wait_all_with_progress
    return asyncio_compat.run(progress_loop_with_timeout)
  File "/home/deena/miniconda3/envs/vision-zoo/lib/python3.10/site-packages/wandb/sdk/lib/asyncio_compat.py", line 30, in run
    return future.result()
  File "/home/deena/miniconda3/envs/vision-zoo/lib/python3.10/concurrent/futures/_base.py", line 458, in result
    return self.__get_result()
  File "/home/deena/miniconda3/envs/vision-zoo/lib/python3.10/concurrent/futures/_base.py", line 403, in __get_result
    raise self._exception
  File "/home/deena/miniconda3/envs/vision-zoo/lib/python3.10/concurrent/futures/thread.py", line 58, in run
    result = self.fn(*self.args, **self.kwargs)
  File "/home/deena/miniconda3/envs/vision-zoo/lib/python3.10/site-packages/wandb/sdk/lib/asyncio_compat.py", line 74, in run
    return asyncio.run(self._run_or_cancel(fn))
  File "/home/deena/miniconda3/envs/vision-zoo/lib/python3.10/asyncio/runners.py", line 44, in run
    return loop.run_until_complete(main)
  File "/home/deena/miniconda3/envs/vision-zoo/lib/python3.10/asyncio/base_events.py", line 649, in run_until_complete
    return future.result()
  File "/home/deena/miniconda3/envs/vision-zoo/lib/python3.10/site-packages/wandb/sdk/lib/asyncio_compat.py", line 98, in _run_or_cancel
    return fn_task.result()
  File "/home/deena/miniconda3/envs/vision-zoo/lib/python3.10/site-packages/wandb/sdk/mailbox/wait_with_progress.py", line 82, in progress_loop_with_timeout
    return await _wait_handles_async(
  File "/home/deena/miniconda3/envs/vision-zoo/lib/python3.10/site-packages/wandb/sdk/mailbox/wait_with_progress.py", line 130, in _wait_handles_async
    async with asyncio_compat.open_task_group() as task_group:
  File "/home/deena/miniconda3/envs/vision-zoo/lib/python3.10/contextlib.py", line 206, in __aexit__
    await anext(self.gen)
  File "/home/deena/miniconda3/envs/vision-zoo/lib/python3.10/site-packages/wandb/sdk/lib/asyncio_compat.py", line 190, in open_task_group
    await task_group._wait_all()
  File "/home/deena/miniconda3/envs/vision-zoo/lib/python3.10/site-packages/wandb/sdk/lib/asyncio_compat.py", line 159, in _wait_all
    raise exc
  File "/home/deena/miniconda3/envs/vision-zoo/lib/python3.10/site-packages/wandb/sdk/mailbox/wait_with_progress.py", line 128, in wait_single
    results[index] = await handle.wait_async(timeout=timeout)
  File "/home/deena/miniconda3/envs/vision-zoo/lib/python3.10/site-packages/wandb/sdk/mailbox/mailbox_handle.py", line 126, in wait_async
    response = await self._handle.wait_async(timeout=timeout)
  File "/home/deena/miniconda3/envs/vision-zoo/lib/python3.10/site-packages/wandb/sdk/mailbox/response_handle.py", line 118, in wait_async
    raise TimeoutError(
TimeoutError: Timed out waiting for response on 3whp25k15vwk

During handling of the above exception, another exception occurred:

Traceback (most recent call last):
  File "/home/deena/miniconda3/envs/vision-zoo/lib/python3.10/site-packages/wandb/sdk/wandb_init.py", line 1468, in init
    return wi.init(run_settings, run_config)
  File "/home/deena/miniconda3/envs/vision-zoo/lib/python3.10/site-packages/wandb/sdk/wandb_init.py", line 954, in init
    raise CommError(
wandb.errors.errors.CommError: Run initialization has timed out after 90.0 sec. Please try increasing the timeout with the `init_timeout` setting: `wandb.init(settings=wandb.Settings(init_timeout=120))`.
2025-03-11 17:32:59,907 INFO    MsgRouterThr:3284794 [mailbox.py:close():129] Closing mailbox, abandoning 1 handles.
